Workbook

Sheet Database
A1: Category | B1: Material Option | C1: Unit Price | D1: Embodied Energy | E1: Social Score
C2: (Rials/m2) | D2: (MJ/m2) | E2: No Dimension
A3: Structural Floors | B3: دال بتنی با 25٪ سرباره | C3: ='M01'!J19 -> 4738265 | D3: ='M01'!T9 -> 594.56 | E3: =Social!C1 -> 3.2307692
A4: Structural Floors | B4: دال بتنی با 30٪ خاکستر بادی | C4: ='M01'!J35 -> 4740620 | D4: ='M01'!T12 -> 580.37 | E4: =Social!C2 -> 3.2307692
A5: Structural Floors | B5: دال بتنی مسلح با بتن درجا | C5: ='M01'!J4 -> 4744940 | D5: ='M01'!T6 -> 641.86 | E5: =Social!C3 -> 3.2307692
A6: Structural Floors | B6: دال مجوف (وافل) | C6: ='M01'!J63 -> 4895745 | D6: ='M01'!T23 -> 496.051 | E6: =Social!C4 -> 4.437247
A7: Structural Floors | B7: دال و تیرچه با یونولیت | C7: ='M01'!J58 -> 3954000 | D7: ='M01'!T20 -> 736.574 | E7: =Social!C5 -> 3.7246964
A8: Structural Floors | B8: دال و تیرچه بلوک | C8: ='M01'!J51 -> 3220000 | D8: ='M01'!T16 -> 581.174 | E8: =Social!C6 -> 2.9595142
A9: Structural Floors | B9: دال کامپوزیت عرشه فولادی | C9: ='M01'!J81 -> 4636120 | D9: ='M01'!T27 -> 532.323 | E9: =Social!C7 -> 3.659919
A10: Architectural Floors | B10: کف بتنی | C10: ='M05'!H29 -> 3298000 | D10: ='M05'!T15 -> 68.585 | E10: =Social!C8 -> 3.2550607
A11: Architectural Floors | B11: کف سرامیک | C11: ='M05'!H9 -> 1313000 | D11: ='M05'!T6 -> 197.7452 | E11: =Social!C9 -> 3.4291498
A12: Architectural Floors | B12: کف سنگ پلاک | C12: ='M05'!H25 -> 2540000 | D12: ='M05'!T14 -> 262.1452 | E12: =Social!C10 -> 3.9919028
A13: Architectural Floors | B13: کف موزاییک | C13: ='M05'!H33 -> 772000 | D13: ='M05'!T22 -> 97.9532 | E13: =Social!C11 -> 2.0040486
A14: Architectural Floors | B14: کف‌پوش لمینت | C14: ='M05'!H36 -> 1890000 | D14: ='M05'!U23 -> 277 | E14: =Social!C12 -> 4.1093117
A15: Architectural Floors | B15: کف‌پوش وینیل (PVC) | C15: ='M05'!H18 -> 1653000 | D15: ='M05'!T7 -> 165.76 | E15: =Social!C13 -> 3.2408907
A16: Exterior Walls | B16: خارجی - دیوار آجری مجوف با دو طرف گچ | C16: ='M03'!H16 -> 2534400 | D16: ='M03'!T10 -> 837.8 | E16: =Social!C14 -> 2.5708502
A17: Exterior Walls | B17: خارجی - دیوار آجری معمولی با دو طرف گچ | C17: ='M03'!H9 -> 2243400 | D17: ='M03'!T6 -> 1639.7 | E17: =Social!C15 -> 2.2307692
A18: Exterior Walls | B18: خارجی - دیوار بلوک بتنی پیش‌ساخته با دو طرف گچ | C18: ='M03'!H48 -> 3096000 | D18: ='M03'!T23 -> 481 | E18: =Social!C16 -> 4.3198381
A19: Exterior Walls | B19: خارجی - دیوار بلوک سبک اتوکلاو شده با دو طرف گچ | C19: ='M03'!H41 -> 2346400 | D19: ='M03'!T22 -> 338.5744 | E19: =Social!C17 -> 3.9716599
A20: Exterior Walls | B20: خارجی - دیوار بلوک سفالی با دو طرف گچ | C20: ='M03'!H23 -> 2011200 | D20: ='M03'!T14 -> 335.208 | E20: =Social!C18 -> 3.5222672
A21: Exterior Walls | B21: خارجی - دیوار بلوک لیکا با دو طرف گچ | C21: ='M03'!H30 -> 2197400 | D21: ='M03'!T18 -> 241.3936 | E21: =Social!C19 -> 3.9109312
A22: Exterior Walls | B22: خارجی - دیوار تری‌دی پانل با شاتکریت با دو طرف گچ | C22: ='M03'!H62 -> 2049000 | D22: ='M03'!T35 -> 441.844 | E22: =Social!C20 -> 4.7935223
A23: Exterior Walls | B23: خارجی - دیوار ساندویچ پانل آلومینیومی | C23: ='M03'!H65 -> 4806000 | D23: ='M03'!T38 -> 900.528 | E23: =Social!C21 -> 3.4251012
A24: Exterior Walls | B24: خارجی - دیوار ساندویچ پانل استیل | C24: ='M03'!H68 -> 4969000 | D24: ='M03'!T41 -> 428.736 | E24: =Social!C22 -> 3.8825911
A25: Exterior Walls | B25: خارجی - دیوار پانل گچی (کناف) با دو طرف گچ | C25: ='M03'!H56 -> 3015700 | D25: ='M03'!T30 -> 379.3 | E25: =Social!C23 -> 4.1700405
A26: Interior Walls | B26: داخلی - دیوار آجری مجوف با دو طرف گچ | C26: ='M04'!H16 -> 1793900 | D26: ='M04'!T10 -> 392.3 | E26: =Social!C24 -> 2.5708502
A27: Interior Walls | B27: داخلی - دیوار آجری معمولی با دو طرف گچ | C27: ='M04'!H9 -> 1658400 | D27: ='M04'!T6 -> 748.7 | E27: =Social!C25 -> 2.2307692
A28: Interior Walls | B28: داخلی - دیوار بلوک بتنی پیش‌ساخته با دو طرف گچ | C28: ='M04'!H48 -> 2371000 | D28: ='M04'!T23 -> 366 | E28: =Social!C26 -> 4.3198381
A29: Interior Walls | B29: داخلی - دیوار بلوک سبک اتوکلاو شده با دو طرف گچ | C29: ='M04'!H41 -> 1756900 | D29: ='M04'!T22 -> 169.2872 | E29: =Social!C27 -> 3.9716599
A30: Interior Walls | B30: داخلی - دیوار بلوک سفالی با دو طرف گچ | C30: ='M04'!H23 -> 1496400 | D30: ='M04'!T14 -> 167.604 | E30: =Social!C28 -> 3.5222672
A31: Interior Walls | B31: داخلی - دیوار بلوک لیکا با دو طرف گچ | C31: ='M04'!H30 -> 1788900 | D31: ='M04'!T18 -> 120.6968 | E31: =Social!C29 -> 3.9109312
A32: Interior Walls | B32: داخلی - دیوار تری‌دی پانل با شاتکریت با دو طرف گچ | C32: ='M04'!H62 -> 1595500 | D32: ='M04'!T35 -> 320.458 | E32: =Social!C30 -> 4.7935223
A33: Interior Walls | B33: داخلی - دیوار پانل گچی (کناف) با دو طرف گچ | C33: ='M04'!H56 -> 2738200 | D33: ='M04'!T30 -> 250.97 | E33: =Social!C31 -> 4.1700405

Sheet M01
A1: محاسبه هزینه | L1: محاسبه انرژی نهفته | W1: محاسبه پایداری اجتماعی
A2: M01 | B2: سازه کف Floor Slabs | L2: M01 | M2: سازه کف Floor Slabs | U2: EDGE
A3: # | B3: Options | C3: گزینه | D3: WBS | E3: بند فهرست بها | F3: شرح بند | G3: واحد | H3: بهای واحد (ریال) | I3: مقدار | J3: بهای کل (ریال) | L3: # | M3: Options | N3: گزینه | O3: جزء تشکیل دهنده | P3: ضخامت(m) | Q3: چگالی(kg/m3) | R3: وزن(kg/m2) | S3: انرژی نهفته واحد وزن (MJ/kg) | T3: انرژی نهفته هر جزء(MJ/m2) | U3: انرژی نهفته کل(MJ/m2)
A4: 1.01 | B4: In-Situ Reinforced Concrete Slab | C4: دال بتنی مسلح با بتن درجا | D4: قالب‌بندی | E4: 060401 | F4: تهیه وسایل و قالببندی با استفاده از قالب فولادی در تاوهها (دالها) تا ارتفاع حداکثر ٣٫۵ متر. | G4: متر مربع | H4: 1148000 | I4: 1 | J4: =SUMPRODUCT(H4:H18,I4:I18) -> 4744940 | L4: 1.01 | M4: In-Situ Reinforced Concrete Slab | N4: دال بتنی مسلح با بتن درجا | O4: بتن | P4: 0.2 | Q4: 2365 | R4: =P4*Q4 -> 473 | S4: 0.82 | T4: =R4*S4 -> 387.86 | U4: 1148
E5: 060402 | F5: تهیه وسایل و قالببندی با استفاده از قالب فولادی در تاوهها (دالها) که ارتفاع بیش از ٣٫۵ متر و حداکثر ۵٫۵ متر باشد. | G5: متر مربع | H5: 1284000 | O5: آرماتور | P5: - | Q5: 7850 | R5: 20 | S5: 12.7 | T5: =R5*S5 -> 254 | U5: 35 cm
E6: 060403 | F6: تهیه وسایل و قالببندی با استفاده از قالب فولادی در تاوهها (دالها) که ارتفاع بیش از ۵٫۵متر و حداکثر ٧٫۵متر باشد | G6: متر مربع | H6: 1470000 | O6: مجموع | T6: =T4+T5 -> 641.86 | U6: 35kg/m2 آرماتور
E7: 060404 | F7: تهیه وسایل و قالببندی با استفاده از قالب فولادی در تاوهها (دالها) که ارتفاع بیش از ٧٫۵ متر و حداکثر١٠ متر باشد. | G7: متر مربع | H7: 1695000 | L7: 1.02 | M7: In-Situ Concrete with >25% GGBS | N7: دال بتنی با >۲۵٪ سرباره | O7: بتن با سرباره | P7: 0.2 | Q7: 2365 | R7: =P7*Q7 -> 473 | S7: 0.72 | T7: =R7*S7 -> 340.56 | U7: 595
D8: آرماتوربندی | E8: 070201 | F8: تهیه، بریدن، خم کردن و کار گذاشتن میلگرد آجدار به قطر تا ١٠میلیمتر، برای بتن مسلح با سیم پیچی لازم | G8: کیلوگرم | H8: 156000 | O8: آرماتور | P8: - | Q8: 7850 | R8: 20 | S8: 12.7 | T8: =R8*S8 -> 254 | U8: 20 cm
E9: 070202 | F9: تهیه، بریدن، خم کردن و کار گذاشتن میلگرد آجدار به قطر 10 تا 2٠میلیمتر، برای بتن مسلح با سیم پیچی لازم | G9: کیلوگرم | H9: 136000 | I9: 20 | O9: مجموع | T9: =T7+T8 -> 594.56 | U9: 20kg/m2 آرماتور
E10: 070203 | F10: تهیه، بریدن، خم کردن و کار گذاشتن میلگرد آجدار به قطر ٢٠تا ۴٠میلیمتر، برای بتن مسلح با سیم پیچی لازم | G10: کیلوگرم | H10: 132000 | L10: 1.03 | M10: In-Situ Concrete with >30% PFA | N10: دال بتنی با >30٪ خاکستر بادی | O10: بتن با خاکستر بادی | P10: 0.2 | Q10: 2365 | R10: =P10*Q10 -> 473 | S10: 0.69 | T10: =R10*S10 -> 326.37 | U10: 605
D11: بتن‌ریزی | E11: 080103 | F11: تهیه و اجرای بتن با شن و ماسه شسته طبیعی یا شکسته با مقاومت فشاری مشخصه 1٢مگاپاسکال | G11: متر مکعب | H11: 3949000 | O11: آرماتور | P11: - | Q11: 7850 | R11: 20 | S11: 12.7 | T11: =R11*S11 -> 254 | U11: 20 cm
E12: 080104 | F12: تهیه و اجرای بتن با شن و ماسه شسته طبیعی یا شکسته با مقاومت فشاری مشخصه 16مگاپاسکال | G12: متر مکعب | H12: 4164000 | O12: مجموع | T12: =T10+T11 -> 580.37 | U12: 20kg/m2 آرماتور
E13: 080105 | F13: تهیه و اجرای بتن با شن و ماسه شسته طبیعی یا شکسته با مقاومت فشاری مشخصه ٢٠مگاپاسکال | G13: متر مکعب | H13: 4256000 | L13: 1.04 | M13: Concrete Filler Slab | N13: دال و تیرچه بلوک (سفالی / سیمانی) | O13: بتن | P13: 0.18 | Q13: 2365 | R13: =P13*Q13 -> 425.7 | S13: 0.82 | T13: =R13*S13 -> 349.074 | U13: 471
E14: 080106 | F14: تهیه و اجرای بتن با شن و ماسه شسته طبیعی یا شکسته با مقاومت فشاری مشخصه ٢۵مگاپاسکال | G14: متر مکعب | H14: 4349000 | I14: 0.2 | O14: آرماتور | P14: - | Q14: 7850 | R14: 11 | S14: 12.7 | T14: =R14*S14 -> 139.7 | U14: 20 cm
E15: 080107 | F15: تهیه و اجرای بتن با شن و ماسه شسته طبیعی یا شکسته با مقاومت فشاری مشخصه ٣٠مگاپاسکال | G15: متر مکعب | H15: 4470000 | O15: بلوک پر کننده | P15: - | Q15: 1606 | R15: =10*14 -> 140 | S15: 0.66 | T15: =R15*S15 -> 92.4 | U15: 11kg/m2 آرماتور
E16: 080108 | F16: تهیه و اجرای بتن با شن و ماسه شسته طبیعی یا شکسته با مقاومت فشاری مشخصه 35مگاپاسکال | G16: متر مکعب | H16: 4536000 | O16: مجموع | T16: =T13+T14+T15 -> 581.174
E17: 080109 | F17: تهیه و اجرای بتن با شن و ماسه شسته طبیعی یا شکسته با مقاومت فشاری مشخصه 40مگاپاسکال | G17: متر مکعب | H17: 4673000 | L17: 1.06 | M17: Concrete Filler Slab with Polystyrene Insulation | N17: دال و تیرچه بلوک با یونولیت | O17: بتن | P17: 0.18 | Q17: 2365 | R17: =P17*Q17 -> 425.7 | S17: 0.82 | T17: =R17*S17 -> 349.074 | U17: 536
E18: 080310 | F18: اضافه بها به ردیف‌های بتن‌ریزی، در صورت مصرف بتن در بتن مسلح | G18: متر مکعب | H18: 35700 | I18: 0.2 | O18: آرماتور | P18: - | Q18: 7850 | R18: 11 | S18: 12.7 | T18: =R18*S18 -> 139.7 | U18: 20 cm
A19: 1.02 | B19: In-Situ Concrete with >25% GGBS | C19: دال بتنی با >۲۵٪ سرباره | D19: قالب‌بندی | E19: 060401 | F19: تهیه وسایل و قالببندی با استفاده از قالب فولادی در تاوهها (دالها) تا ارتفاع حداکثر ٣٫۵ متر. | G19: متر مربع | H19: 1148000 | I19: 1 | J19: =SUMPRODUCT(H19:H33,I19:I33)-(2399-H34)*0.25*300*0.2 -> 4738265 | O19: پلی‌استایرن | Q19: 20 | R19: 3 | S19: 82.6 | T19: =R19*S19 -> 247.8 | U19: 11kg/m2 آرماتور
E20: 060402 | F20: تهیه وسایل و قالببندی با استفاده از قالب فولادی در تاوهها (دالها) که ارتفاع بیش از ٣٫۵ متر و حداکثر ۵٫۵ متر باشد. | G20: متر مربع | H20: 1284000 | O20: مجموع | T20: =T17+T18+T19 -> 736.574
E21: 060403 | F21: تهیه وسایل و قالببندی با استفاده از قالب فولادی در تاوهها (دالها) که ارتفاع بیش از ۵٫۵متر و حداکثر ٧٫۵متر باشد | G21: متر مربع | H21: 1470000 | L21: 1.08 | M21: In-Situ Waffle Concrete Slab | N21: دال مجوف (وافل) | O21: بتن | P21: 0.17 | Q21: 2365 | R21: =P21*Q21 -> 402.05 | S21: 0.82 | T21: =R21*S21 -> 329.681 | U21: 568
E22: 060404 | F22: تهیه وسایل و قالببندی با استفاده از قالب فولادی در تاوهها (دالها) که ارتفاع بیش از ٧٫۵ متر و حداکثر١٠ متر باشد. | G22: متر مربع | H22: 1695000 | O22: آرماتور | P22: - | Q22: 7850 | R22: 13.1 | S22: 12.7 | T22: =R22*S22 -> 166.37 | U22: 35 cm
D23: آرماتوربندی | E23: 070201 | F23: تهیه، بریدن، خم کردن و کار گذاشتن میلگرد آجدار به قطر تا ١٠میلیمتر، برای بتن مسلح با سیم پیچی لازم | G23: کیلوگرم | H23: 156000 | O23: مجموع | T23: =T21+T22 -> 496.051 | U23: 13.1kg/m2 آرماتور
E24: 070202 | F24: تهیه، بریدن، خم کردن و کار گذاشتن میلگرد آجدار به قطر 10 تا 2٠میلیمتر، برای بتن مسلح با سیم پیچی لازم | G24: کیلوگرم | H24: 136000 | I24: 20 | L24: 1.11 | M24: Composite in-situ concrete and steel deck (permanent shuttering) | N24: کف کامپوزیت عرشه فولادی | O24: بتن | P24: 0.11 | Q24: 2365 | R24: =P24*Q24 -> 260.15 | S24: 0.82 | T24: =R24*S24 -> 213.323 | U24: 407
E25: 070203 | F25: تهیه، بریدن، خم کردن و کار گذاشتن میلگرد آجدار به قطر ٢٠تا ۴٠میلیمتر، برای بتن مسلح با سیم پیچی لازم | G25: کیلوگرم | H25: 132000 | O25: آرماتور | P25: - | Q25: 7850 | R25: 10 | S25: 12.7 | T25: =R25*S25 -> 127 | U25: 10 cm
D26: بتن‌ریزی | E26: 080103 | F26: تهیه و اجرای بتن با شن و ماسه شسته طبیعی یا شکسته با مقاومت فشاری مشخصه 1٢مگاپاسکال | G26: متر مکعب | H26: 3949000 | O26: ورق گالوانیزه | P26: 0.00125 | Q26: 7850 | R26: 10 | S26: 19.2 | T26: =R26*S26 -> 192 | U26: 10kg/m2 آرماتور
E27: 080104 | F27: تهیه و اجرای بتن با شن و ماسه شسته طبیعی یا شکسته با مقاومت فشاری مشخصه 16مگاپاسکال | G27: متر مکعب | H27: 4164000 | O27: مجموع | T27: =T24+T25+T26 -> 532.323
E28: 080105 | F28: تهیه و اجرای بتن با شن و ماسه شسته طبیعی یا شکسته با مقاومت فشاری مشخصه ٢٠مگاپاسکال | G28: متر مکعب | H28: 4256000
E29: 080106 | F29: تهیه و اجرای بتن با شن و ماسه شسته طبیعی یا شکسته با مقاومت فشاری مشخصه ٢۵مگاپاسکال | G29: متر مکعب | H29: 4349000 | I29: 0.2
E30: 080107 | F30: تهیه و اجرای بتن با شن و ماسه شسته طبیعی یا شکسته با مقاومت فشاری مشخصه ٣٠مگاپاسکال | G30: متر مکعب | H30: 4470000
E31: 080108 | F31: تهیه و اجرای بتن با شن و ماسه شسته طبیعی یا شکسته با مقاومت فشاری مشخصه 35مگاپاسکال | G31: متر مکعب | H31: 4536000
E32: 080109 | F32: تهیه و اجرای بتن با شن و ماسه شسته طبیعی یا شکسته با مقاومت فشاری مشخصه 40مگاپاسکال | G32: متر مکعب | H32: 4673000
E33: 080310 | F33: اضافه بها به ردیف‌های بتن‌ریزی، در صورت مصرف بتن در بتن مسلح | G33: متر مکعب | H33: 35700 | I33: 0.2 | K33: قیمت سیمان | L33: 2399/kg
D34: مواد افزودنی | E34: سرباره | F34: هزینه تهیه یک کیلوگرم سرباره (محاسبه هزینه نهایی بر اساس کیلوگرم در هر مترمکعب) | G34: کیلوگرم | H34: 1954 | K34: فرض عیار سیمان | L34: 300kg/m3
A35: 1.03 | B35: In-Situ Concrete with >30% PFA | C35: دال بتنی با >30٪ خاکستر بادی | D35: قالب‌بندی | E35: 060401 | F35: تهیه وسایل و قالببندی با استفاده از قالب فولادی در تاوهها (دالها) تا ارتفاع حداکثر ٣٫۵ متر. | G35: متر مربع | H35: 1148000 | I35: 1 | J35: =SUMPRODUCT(H35:H49,I35:I49)-(2399-H50)*0.3*300*0.2 -> 4740620
E36: 060402 | F36: تهیه وسایل و قالببندی با استفاده از قالب فولادی در تاوهها (دالها) که ارتفاع بیش از ٣٫۵ متر و حداکثر ۵٫۵ متر باشد. | G36: متر مربع | H36: 1284000
E37: 060403 | F37: تهیه وسایل و قالببندی با استفاده از قالب فولادی در تاوهها (دالها) که ارتفاع بیش از ۵٫۵متر و حداکثر ٧٫۵متر باشد | G37: متر مربع | H37: 1470000
E38: 060404 | F38: تهیه وسایل و قالببندی با استفاده از قالب فولادی در تاوهها (دالها) که ارتفاع بیش از ٧٫۵ متر و حداکثر١٠ متر باشد. | G38: متر مربع | H38: 1695000
D39: آرماتوربندی | E39: 070201 | F39: تهیه، بریدن، خم کردن و کار گذاشتن میلگرد آجدار به قطر تا ١٠میلیمتر، برای بتن مسلح با سیم پیچی لازم | G39: کیلوگرم | H39: 156000
E40: 070202 | F40: تهیه، بریدن، خم کردن و کار گذاشتن میلگرد آجدار به قطر 10 تا 2٠میلیمتر، برای بتن مسلح با سیم پیچی لازم | G40: کیلوگرم | H40: 136000 | I40: 20
...

Sheet M02
A1: M02 | B1: سقف Roof Construction | L1: M02 | M1: سقف Roof Construction | U1: EDGE
A2: # | B2: Options | C2: گزینه | D2: WBS | E2: بند فهرست بها | F2: شرح بند | G2: واحد | H2: بهای واحد (ریال) | I2: مقدار | J2: بهای کل (ریال) | L2: # | M2: Options | N2: گزینه | O2: جزء تشکیل دهنده | P2: ضخامت(m) | Q2: چگالی(kg/m3) | R2: وزن(kg/m2) | S2: انرژی نهفته واحد وزن (MJ/kg) | T2: انرژی نهفته هر جزء(MJ/m2) | U2: انرژی نهفته کل(MJ/m2)
A3: 2.01 | B3: In-Situ Reinforced Concrete Slab | C3: دال بتنی مسلح با بتن درجا | D3: قالب‌بندی | E3: 060401 | F3: تهیه وسایل و قالببندی با استفاده از قالب فولادی در تاوهها (دالها) تا ارتفاع حداکثر ٣٫۵ متر. | G3: متر مربع | H3: 1148000 | I3: 1 | J3: =SUMPRODUCT(H3:H17,I3:I17) -> 7442645 | L3: 2.01 | M3: In-Situ Reinforced Concrete Slab | N3: دال بتنی مسلح با بتن درجا | O3: بتن | P3: 0.35 | Q3: 2365 | R3: =P3*Q3 -> 827.75 | S3: 0.82 | T3: =R3*S3 -> 678.755 | U3: 1148
E4: 060402 | F4: تهیه وسایل و قالببندی با استفاده از قالب فولادی در تاوهها (دالها) که ارتفاع بیش از ٣٫۵ متر و حداکثر ۵٫۵ متر باشد. | G4: متر مربع | H4: 1284000 | O4: آرماتور | P4: - | Q4: 7850 | R4: 35 | S4: 12.7 | T4: =R4*S4 -> 444.5 | U4: 35 cm
E5: 060403 | F5: تهیه وسایل و قالببندی با استفاده از قالب فولادی در تاوهها (دالها) که ارتفاع بیش از ۵٫۵متر و حداکثر ٧٫۵متر باشد | G5: متر مربع | H5: 1470000 | O5: مجموع | T5: =T3+T4 -> 1123.255 | U5: 35kg/m2 آرماتور
E6: 060404 | F6: تهیه وسایل و قالببندی با استفاده از قالب فولادی در تاوهها (دالها) که ارتفاع بیش از ٧٫۵ متر و حداکثر١٠ متر باشد. | G6: متر مربع | H6: 1695000 | L6: 2.02 | M6: In-Situ Concrete with >25% GGBS | N6: دال بتنی با >۲۵٪ سرباره | O6: بتن با سرباره | P6: 0.2 | Q6: 2365 | R6: =P6*Q6 -> 473 | S6: 0.72 | T6: =R6*S6 -> 340.56 | U6: 595
D7: آرماتوربندی | E7: 070201 | F7: تهیه، بریدن، خم کردن و کار گذاشتن میلگرد آجدار به قطر تا ١٠میلیمتر، برای بتن مسلح با سیم پیچی لازم | G7: کیلوگرم | H7: 156000 | O7: آرماتور | P7: - | Q7: 7850 | R7: 20 | S7: 12.7 | T7: =R7*S7 -> 254 | U7: 20 cm
E8: 070202 | F8: تهیه، بریدن، خم کردن و کار گذاشتن میلگرد آجدار به قطر 10 تا 2٠میلیمتر، برای بتن مسلح با سیم پیچی لازم | G8: کیلوگرم | H8: 136000 | I8: 35 | O8: مجموع | T8: =T6+T7 -> 594.56 | U8: 20kg/m2 آرماتور
E9: 070203 | F9: تهیه، بریدن، خم کردن و کار گذاشتن میلگرد آجدار به قطر ٢٠تا ۴٠میلیمتر، برای بتن مسلح با سیم پیچی لازم | G9: کیلوگرم | H9: 132000 | L9: 2.03 | M9: In-Situ Concrete with >30% PFA | N9: دال بتنی با >30٪ خاکستر بادی | O9: بتن با خاکستر بادی | P9: 0.2 | Q9: 2365 | R9: =P9*Q9 -> 473 | S9: 0.69 | T9: =R9*S9 -> 326.37 | U9: 605
D10: بتن‌ریزی | E10: 080103 | F10: تهیه و اجرای بتن با شن و ماسه شسته طبیعی یا شکسته با مقاومت فشاری مشخصه 1٢مگاپاسکال | G10: متر مکعب | H10: 3949000 | O10: آرماتور | P10: - | Q10: 7850 | R10: 20 | S10: 12.7 | T10: =R10*S10 -> 254 | U10: 20 cm
E11: 080104 | F11: تهیه و اجرای بتن با شن و ماسه شسته طبیعی یا شکسته با مقاومت فشاری مشخصه 16مگاپاسکال | G11: متر مکعب | H11: 4164000 | O11: مجموع | T11: =T9+T10 -> 580.37 | U11: 20kg/m2 آرماتور
E12: 080105 | F12: تهیه و اجرای بتن با شن و ماسه شسته طبیعی یا شکسته با مقاومت فشاری مشخصه ٢٠مگاپاسکال | G12: متر مکعب | H12: 4256000 | L12: 2.04 | M12: Concrete Filler Slab | N12: دال و تیرچه بلوک (سفالی / سیمانی) | O12: بتن | P12: 0.18 | Q12: 2365 | R12: =P12*Q12 -> 425.7 | S12: 0.82 | T12: =R12*S12 -> 349.074 | U12: 471
E13: 080106 | F13: تهیه و اجرای بتن با شن و ماسه شسته طبیعی یا شکسته با مقاومت فشاری مشخصه ٢۵مگاپاسکال | G13: متر مکعب | H13: 4349000 | I13: 0.35 | O13: آرماتور | P13: - | Q13: 7850 | R13: 11 | S13: 12.7 | T13: =R13*S13 -> 139.7 | U13: 20 cm
E14: 080107 | F14: تهیه و اجرای بتن با شن و ماسه شسته طبیعی یا شکسته با مقاومت فشاری مشخصه ٣٠مگاپاسکال | G14: متر مکعب | H14: 4470000 | O14: بلوک پر کننده | P14: - | Q14: 1606 | R14: =10*14 -> 140 | S14: 0.66 | T14: =R14*S14 -> 92.4 | U14: 11kg/m2 آرماتور
E15: 080108 | F15: تهیه و اجرای بتن با شن و ماسه شسته طبیعی یا شکسته با مقاومت فشاری مشخصه 35مگاپاسکال | G15: متر مکعب | H15: 4536000 | O15: مجموع | T15: =T12+T13+T14 -> 581.174
E16: 080109 | F16: تهیه و اجرای بتن با شن و ماسه شسته طبیعی یا شکسته با مقاومت فشاری مشخصه 40مگاپاسکال | G16: متر مکعب | H16: 4673000 | L16: 2.06 | M16: Concrete Filler Slab with Polystyrene Insulation | N16: دال و تیرچه بلوک با یونولیت | O16: بتن | P16: 0.18 | Q16: 2365 | R16: =P16*Q16 -> 425.7 | S16: 0.82 | T16: =R16*S16 -> 349.074 | U16: 536
E17: 080310 | F17: اضافه بها به ردیف‌های بتن‌ریزی، در صورت مصرف بتن در بتن مسلح | G17: متر مکعب | H17: 35700 | I17: 0.35 | O17: آرماتور | P17: - | Q17: 7850 | R17: 11 | S17: 12.7 | T17: =R17*S17 -> 139.7 | U17: 20 cm
A18: 2.02 | B18: In-Situ Concrete with >25% GGBS | C18: دال بتنی با >۲۵٪ سرباره | D18: قالب‌بندی | E18: 060401 | F18: تهیه وسایل و قالببندی با استفاده از قالب فولادی در تاوهها (دالها) تا ارتفاع حداکثر ٣٫۵ متر. | G18: متر مربع | H18: 1148000 | I18: 1 | J18: =SUMPRODUCT(H18:H32,I18:I32)-(2399-1954)*0.25*300*0.2 -> 4738265 | O18: پلی‌استایرن | Q18: 20 | R18: 3 | S18: 82.6 | T18: =R18*S18 -> 247.8 | U18: 11kg/m2 آرماتور
E19: 060402 | F19: تهیه وسایل و قالببندی با استفاده از قالب فولادی در تاوهها (دالها) که ارتفاع بیش از ٣٫۵ متر و حداکثر ۵٫۵ متر باشد. | G19: متر مربع | H19: 1284000 | O19: مجموع | T19: =T16+T17+T18 -> 736.574
E20: 060403 | F20: تهیه وسایل و قالببندی با استفاده از قالب فولادی در تاوهها (دالها) که ارتفاع بیش از ۵٫۵متر و حداکثر ٧٫۵متر باشد | G20: متر مربع | H20: 1470000 | L20: 2.08 | M20: In-Situ Waffle Concrete Slab | N20: دال مجوف (وافل) | O20: بتن | P20: 0.17 | Q20: 2365 | R20: =P20*Q20 -> 402.05 | S20: 0.82 | T20: =R20*S20 -> 329.681 | U20: 568
E21: 060404 | F21: تهیه وسایل و قالببندی با استفاده از قالب فولادی در تاوهها (دالها) که ارتفاع بیش از ٧٫۵ متر و حداکثر١٠ متر باشد. | G21: متر مربع | H21: 1695000 | O21: آرماتور | P21: - | Q21: 7850 | R21: 13.1 | S21: 12.7 | T21: =R21*S21 -> 166.37 | U21: 35 cm
D22: آرماتوربندی | E22: 070201 | F22: تهیه، بریدن، خم کردن و کار گذاشتن میلگرد آجدار به قطر تا ١٠میلیمتر، برای بتن مسلح با سیم پیچی لازم | G22: کیلوگرم | H22: 156000 | O22: مجموع | T22: =T20+T21 -> 496.051 | U22: 13.1kg/m2 آرماتور
E23: 070202 | F23: تهیه، بریدن، خم کردن و کار گذاشتن میلگرد آجدار به قطر 10 تا 2٠میلیمتر، برای بتن مسلح با سیم پیچی لازم | G23: کیلوگرم | H23: 136000 | I23: 20 | L23: 2.11 | M23: Composite in-situ concrete and steel deck (permanent shuttering) | N23: کف کامپوزیت عرشه فولادی | O23: بتن | P23: 0.11 | Q23: 2365 | R23: =P23*Q23 -> 260.15 | S23: 0.82 | T23: =R23*S23 -> 213.323 | U23: 407
E24: 070203 | F24: تهیه، بریدن، خم کردن و کار گذاشتن میلگرد آجدار به قطر ٢٠تا ۴٠میلیمتر، برای بتن مسلح با سیم پیچی لازم | G24: کیلوگرم | H24: 132000 | O24: آرماتور | P24: - | Q24: 7850 | R24: 10 | S24: 12.7 | T24: =R24*S24 -> 127 | U24: 10 cm
D25: بتن‌ریزی | E25: 080103 | F25: تهیه و اجرای بتن با شن و ماسه شسته طبیعی یا شکسته با مقاومت فشاری مشخصه 1٢مگاپاسکال | G25: متر مکعب | H25: 3949000 | O25: ورق گالوانیزه | P25: 0.00125 | Q25: 7850 | R25: 10 | S25: 19.2 | T25: =R25*S25 -> 192 | U25: 10kg/m2 آرماتور
E26: 080104 | F26: تهیه و اجرای بتن با شن و ماسه شسته طبیعی یا شکسته با مقاومت فشاری مشخصه 16مگاپاسکال | G26: متر مکعب | H26: 4164000 | O26: مجموع | T26: =T23+T24+T25 -> 532.323
E27: 080105 | F27: تهیه و اجرای بتن با شن و ماسه شسته طبیعی یا شکسته با مقاومت فشاری مشخصه ٢٠مگاپاسکال | G27: متر مکعب | H27: 4256000
E28: 080106 | F28: تهیه و اجرای بتن با شن و ماسه شسته طبیعی یا شکسته با مقاومت فشاری مشخصه ٢۵مگاپاسکال | G28: متر مکعب | H28: 4349000 | I28: 0.2
E29: 080107 | F29: تهیه و اجرای بتن با شن و ماسه شسته طبیعی یا شکسته با مقاومت فشاری مشخصه ٣٠مگاپاسکال | G29: متر مکعب | H29: 4470000
E30: 080108 | F30: تهیه و اجرای بتن با شن و ماسه شسته طبیعی یا شکسته با مقاومت فشاری مشخصه 35مگاپاسکال | G30: متر مکعب | H30: 4536000
E31: 080109 | F31: تهیه و اجرای بتن با شن و ماسه شسته طبیعی یا شکسته با مقاومت فشاری مشخصه 40مگاپاسکال | G31: متر مکعب | H31: 4673000
E32: 080310 | F32: اضافه بها به ردیف‌های بتن‌ریزی، در صورت مصرف بتن در بتن مسلح | G32: متر مکعب | H32: 35700 | I32: 0.2
D33: مواد افزودنی | E33: سرباره | F33: هزینه تهیه یک کیلوگرم سرباره (محاسبه هزینه نهایی بر اساس کیلوگرم در هر مترمکعب) | G33: کیلوگرم | H33: 1954
A34: 2.03 | B34: In-Situ Concrete with >30% PFA | C34: دال بتنی با >30٪ خاکستر بادی | D34: قالب‌بندی | E34: 060401 | F34: تهیه وسایل و قالببندی با استفاده از قالب فولادی در تاوهها (دالها) تا ارتفاع حداکثر ٣٫۵ متر. | G34: متر مربع | H34: 1148000 | I34: 1 | J34: =SUMPRODUCT(H34:H48,I34:I48)-(2399-H49)*0.3*300*0.2 -> 4740620
E35: 060402 | F35: تهیه وسایل و قالببندی با استفاده از قالب فولادی در تاوهها (دالها) که ارتفاع بیش از ٣٫۵ متر و حداکثر ۵٫۵ متر باشد. | G35: متر مربع | H35: 1284000
E36: 060403 | F36: تهیه وسایل و قالببندی با استفاده از قالب فولادی در تاوهها (دالها) که ارتفاع بیش از ۵٫۵متر و حداکثر ٧٫۵متر باشد | G36: متر مربع | H36: 1470000
E37: 060404 | F37: تهیه وسایل و قالببندی با استفاده از قالب فولادی در تاوهها (دالها) که ارتفاع بیش از ٧٫۵ متر و حداکثر١٠ متر باشد. | G37: متر مربع | H37: 1695000
D38: آرماتوربندی | E38: 070201 | F38: تهیه، بریدن، خم کردن و کار گذاشتن میلگرد آجدار به قطر تا ١٠میلیمتر، برای بتن مسلح با سیم پیچی لازم | G38: کیلوگرم | H38: 156000
E39: 070202 | F39: تهیه، بریدن، خم کردن و کار گذاشتن میلگرد آجدار به قطر 10 تا 2٠میلیمتر، برای بتن مسلح با سیم پیچی لازم | G39: کیلوگرم | H39: 136000 | I39: 20
E40: 070203 | F40: تهیه، بریدن، خم کردن و کار گذاشتن میلگرد آجدار به قطر ٢٠تا ۴٠میلیمتر، برای بتن مسلح با سیم پیچی لازم | G40: کیلوگرم | H40: 132000
...

Sheet M03
A1: M03 | B1: دیوارهای خارجی External Walls | L1: M03 | M1: دیوارهای خارجی External Walls | U1: EDGE
A2: # | B2: Options | C2: گزینه | D2: WBS | E2: بند فهرست بها | F2: شرح بند | G2: واحد | H2: بهای واحد (ریال) | I2: مقدار | J2: بهای کل (ریال) | L2: # | M2: Options | N2: گزینه | O2: جزء تشکیل دهنده | P2: ضخامت(m) | Q2: چگالی(kg/m3) | R2: وزن(kg/m2) | S2: انرژی نهفته واحد وزن (MJ/kg) | T2: انرژی نهفته هر جزء(MJ/m2) | U2: انرژی نهفته کل(MJ/m2)
A3: 3.01 | B3: Common Brick Wall with internal & external plaster | C3: دیوار آجری معمولی با دو طرف گچ | D3: آجرچینی با آجر فشاری | E3: 110201 | F3: آجرکاری به ضخامت یک و نیم آجر و بیشتر با آجر فشاری و ملات ماسه سیمان 1:5 | G3: متر مکعب | H3: 5780000 | L3: 3.01 | M3: Common Brick Wall with internal & external plaster | N3: دیوار آجری معمولی با دو طرف گچ | O3: آجر فشاری | P3: 0.18 | Q3: 1800 | R3: =P3*Q3 -> 324 | S3: 4.95 | T3: =R3*S3 -> 1603.8 | U3: 1616
E4: 110205 | F4: دیوار یک آجره با آجر فشاری و ملات ماسه سیمان 1:5 | G4: متر مربع | H4: 1316000 | I4: 1 | O4: اندود گچ و خاک | P4: 0.01 | Q4: 1600 | R4: =P4*Q4 -> 16 | S4: 1 | T4: =R4*S4 -> 16 | U4: 20 cm
E5: 110208 | F5: دیوار نیم آجره با آجر فشاری و ملات ماسه سیمان 1:5 | G5: متر مربع | H5: 731000 | O5: پلاستر گچ | P5: 0.01 | Q5: 1000 | R5: =P5*Q5 -> 10 | S5: 1.99 | T5: =R5*S5 -> 19.9
D6: اندود گچ و خاک | E6: 180201 | F6: شمشه‌گیری سطوح قائم و سقف‌ها، با ملات گچ و خاک یا گچ | G6: متر مربع | H6: 67200 | I6: 2 | O6: مجموع | T6: =SUM(T3:T5) -> 1639.7
E7: 180202 | F7: اندود گچ و خاک به ضخامت تا 2.5 سانتی‌متر، روی سطوح قائم | G7: متر مربع | H7: 206000 | I7: 2 | L7: 3.02 | M7: Cored (with holes) bricks with internal & external plaster | N7: دیوار آجری مجوف با دو طرف گچ | O7: آجر مجوف | P7: 0.18 | Q7: 1800 | R7: =P7*Q7*0.5 -> 162 | S7: 4.95 | T7: =R7*S7 -> 801.9 | U7: 814
D8: سفیدکاری | E8: 180215 | F8: سفیدکاری روی سطوح قائم و پرداخت آن با گچ کشته | G8: متر مربع | H8: 190500 | I8: 2 | O8: اندود گچ و خاک | P8: 0.01 | Q8: 1600 | R8: =P8*Q8 -> 16 | S8: 1 | T8: =R8*S8 -> 16 | U8: 20 cm
F9: مجموع | G9: متر مربع | H9: =SUMPRODUCT(H3:H8,I3:I8) -> 2243400 | O9: پلاستر گچ | P9: 0.01 | Q9: 1000 | R9: =P9*Q9 -> 10 | S9: 1.99 | T9: =R9*S9 -> 19.9
A10: 3.02 | B10: Cored (with holes) bricks with internal & external plaster | C10: دیوار آجری مجوف با دو طرف گچ | D10: آجرچینی با آجر ماشینی سوراخ‌‎دار | E10: 110501 | F10: آجرکاری به ضخامت یک و نیم آجر و بیشتر با آجر ماشینی سواخ‌دار به ابعاد آجر فشاری و ملات ماسه سیمان 1:5 | G10: متر مکعب | H10: 6943000 | O10: مجموع | T10: =SUM(T7:T9) -> 837.8
E11: 110502 | F11: دیوار یک آجره با آجر ماشینی سواخ‌دار به ابعاد آجر فشاری، با ملات ماسه سیمان 1:5 | G11: متر مربع | H11: 1607000 | I11: 1 | L11: 3.03 | M11: Honeycomb Clay Blocks with internal & external plaster | N11: دیوار با بلوک سفالی با دو طرف گچ | O11: بلوک سفالی | P11: 0.16 | Q11: 815 | R11: =P11*Q11 -> 130.4 | S11: 2.02 | T11: =R11*S11 -> 263.408 | U11: 338
E12: 110503 | F12: دیوار نیم آجره با آجر ماشینی سواخ‌دار به ابعاد آجر فشاری، با ملات ماسه سیمان 1:5 | G12: متر مربع | H12: 866500 | O12: اندود گچ و خاک | P12: 0.02 | Q12: 1600 | R12: =P12*Q12 -> 32 | S12: 1 | T12: =R12*S12 -> 32 | U12: 20 cm
D13: اندود گچ و خاک | E13: 180201 | F13: شمشه‌گیری سطوح قائم و سقف‌ها، با ملات گچ و خاک یا گچ | G13: متر مربع | H13: 67200 | I13: 2 | O13: پلاستر گچ | P13: 0.02 | Q13: 1000 | R13: =P13*Q13 -> 20 | S13: 1.99 | T13: =R13*S13 -> 39.8
E14: 180202 | F14: اندود گچ و خاک به ضخامت تا 2.5 سانتی‌متر، روی سطوح قائم | G14: متر مربع | H14: 206000 | I14: 2 | O14: مجموع | T14: =SUM(T11:T13) -> 335.208
D15: سفیدکاری | E15: 180215 | F15: سفیدکاری روی سطوح قائم و پرداخت آن با گچ کشته | G15: متر مربع | H15: 190500 | I15: 2 | L15: 3.04 | M15: Medium Weight Hollow Concrete Blocks | N15: دیوار با بلوک لیکا با دو طرف گچ | O15: بلوک لیکا | P15: 0.16 | Q15: 1606 | R15: =P15*Q15 -> 256.96 | S15: 0.66 | T15: =R15*S15 -> 169.5936 | U15: 234
F16: مجموع | G16: متر مربع | H16: =SUMPRODUCT(H10:H15,I10:I15) -> 2534400 | O16: اندود گچ و خاک | P16: 0.02 | Q16: 1600 | R16: =P16*Q16 -> 32 | S16: 1 | T16: =R16*S16 -> 32 | U16: 20 cm
A17: 3.03 | B17: Honeycomb Clay Blocks with internal & external plaster | C17: دیوار با بلوک سفالی با دو طرف گچ | D17: آجرچینی با بلوک سفالی | E17: 110401 | F17: دیوار به ضخامت 7 تا 11 سانتی‌متر با بلوک سفال و ملات ماسه سیمان 1:5 | G17: متر مکعب | H17: 5690000 | O17: پلاستر گچ | P17: 0.02 | Q17: 1000 | R17: =P17*Q17 -> 20 | S17: 1.99 | T17: =R17*S17 -> 39.8
E18: 110402 | F18: دیوار به ضخامت بیش از 11 تا 22 سانتی‌متر با بلوک سفال و ملات ماسه سیمان 1:5 | G18: متر مکعب | H18: 5419000 | I18: 0.2 | O18: مجموع | T18: =SUM(T15:T17) -> 241.3936
E19: 110403 | F19: آجرکاری به ضخامت بیش از 22 سانتی‌متر با بلوک سفال و ملات ماسه سیمان 1:5 | G19: متر مکعب | H19: 5329000 | L19: 3.06 | M19: Autoclaved Aerated Concrete Blocks | N19: دیوار با بلوک بتنی سبک AAC (هبلکس و ...) | O19: بلوک AAC | P19: 0.16 | Q19: 471 | R19: =P19*Q19 -> 75.36 | S19: 3.54 | T19: =R19*S19 -> 266.7744 | U19: 317
D20: اندود گچ و خاک | E20: 180201 | F20: شمشه‌گیری سطوح قائم و سقف‌ها، با ملات گچ و خاک یا گچ | G20: متر مربع | H20: 67200 | I20: 2 | O20: اندود گچ و خاک | P20: 0.02 | Q20: 1600 | R20: =P20*Q20 -> 32 | S20: 1 | T20: =R20*S20 -> 32 | U20: 20 cm
E21: 180202 | F21: اندود گچ و خاک به ضخامت تا 2.5 سانتی‌متر، روی سطوح قائم | G21: متر مربع | H21: 206000 | I21: 2 | O21: پلاستر گچ | P21: 0.02 | Q21: 1000 | R21: =P21*Q21 -> 20 | S21: 1.99 | T21: =R21*S21 -> 39.8
D22: سفیدکاری | E22: 180215 | F22: سفیدکاری روی سطوح قائم و پرداخت آن با گچ کشته | G22: متر مربع | H22: 190500 | I22: 2 | O22: مجموع | T22: =SUM(T19:T21) -> 338.5744
F23: مجموع | G23: متر مربع | H23: =SUMPRODUCT(H17:H22,I17:I22) -> 2011200 | L23: 3.11 | M23: Precast EPS-based Concrete Panels | N23: دیوار بتنی پیش‌ساخته (والکریت) | O23: بلوک پیش‌ساخته بتنی | P23: 0.15 | Q23: - | R23: - | S23: - | T23: 481 | U23: 481
A24: 3.04 | B24: Medium Weight Hollow Concrete Blocks | C24: دیوار با بلوک لیکا با دو طرف گچ | D24: بنایی با بلوک سیمانی لیکا | E24: 121001 | F24: بنایی با بلوک سیمانی سبک توخالی کف‌پر تهیه شده با دانه رس منبسط شده، به ضخامت تا 10 سانتی‌متر با ملات ماسه و سیمان 1:5 | G24: متر مربع | H24: 861500 | O24: پلاستر گچ | P24: 0.01 | Q24: 1000 | R24: =P24*Q24 -> 10 | S24: 1.99 | T24: =R24*S24 -> 19.9 | U24: 15 cm
E25: 121002 | F25: بنایی با بلوک سیمانی سبک توخالی کف‌پر تهیه شده با دانه رس منبسط شده، به ضخامت 12 تا 15 سانتی‌متر با ملات ماسه و سیمان 1:5 | G25: متر مربع | H25: 1046000
E26: 121003 | F26: بنایی با بلوک سیمانی سبک توخالی کف‌پر تهیه شده با دانه رس منبسط شده، به ضخامت 17 تا 20 سانتی‌متر با ملات ماسه و سیمان 1:5 | G26: متر مربع | H26: 1270000 | I26: 1 | O26: مجموع
D27: اندود گچ و خاک | E27: 180201 | F27: شمشه‌گیری سطوح قائم و سقف‌ها، با ملات گچ و خاک یا گچ | G27: متر مربع | H27: 67200 | I27: 2 | L27: 3.39 | M27: Plasterboards on metal studs | N27: دیوار پانل گچی با فریم فلزی | O27: پانل گچی | P27: 0.02 | Q27: 840 | R27: =P27*Q27 -> 16.8 | S27: 4.1 | T27: =R27*S27 -> 68.88 | U27: 259
E28: 180202 | F28: اندود گچ و خاک به ضخامت تا 2.5 سانتی‌متر، روی سطوح قائم | G28: متر مربع | H28: 206000 | I28: 2 | O28: زیرسازی فلزی | P28: - | Q28: - | R28: 10 | S28: 19.2 | T28: =R28*S28 -> 192 | U28: 20 cm
D29: سفیدکاری | E29: 180215 | F29: سفیدکاری روی سطوح قائم و پرداخت آن با گچ کشته | G29: متر مربع | H29: 190500 | I29: 2 | O29: عایق (پشم سنگ) | P29: 0.2 | Q29: 31 | R29: =P29*Q29 -> 6.2 | S29: 19.1 | T29: =R29*S29 -> 118.42
F30: مجموع | G30: متر مربع | H30: =SUMPRODUCT(H24:H29,I24:I29) -> 2197400 | O30: مجموع | T30: =SUM(T27:T29) -> 379.3
A31: 3.06 | B31: Autoclaved Aerated Concrete Blocks | C31: دیوار با بلوک بتنی سبک AAC (هبلکس و ...) | D31: بلوک از جنس بتن سبک | E31: 120801 | F31: بنایی با بلوک‌های بتنی پیش‌ساخته از بتن سبک اتوکلاو شده (بتن گازی) با ملات مخصوص به ضخامت حدود 10 سانتی‌متر | G31: متر مربع | H31: 829500 | L31: 3.41 | M31: 3-D Wire panel with 'shot-crete' both sides | N31: 3D پانل با شاتکریت طرفین | O31: سازه مشبک آرماتور | P31: - | Q31: - | R31: 8 | S31: 12.7 | T31: =R31*S31 -> 101.6 | U31: 281 | V31: بدون عایق
E32: 120802 | F32: بنایی با بلوک‌های بتنی پیش‌ساخته از بتن سبک اتوکلاو شده (بتن گازی) با ملات مخصوص به ضخامت حدود 15 سانتی‌متر | G32: متر مربع | H32: 1094000 | O32: عایق (پلی‌استایرن) | P32: 0.1 | Q32: 20 | R32: =P32*Q32 -> 2 | S32: 82.6 | T32: =R32*S32 -> 165.2 | U32: 20 cm
E33: 120803 | F33: بنایی با بلوک‌های بتنی پیش‌ساخته از بتن سبک اتوکلاو شده (بتن گازی) با ملات مخصوص به ضخامت حدود 20 سانتی‌متر | G33: متر مربع | H33: 1419000 | I33: 1 | O33: بتن شاتکریت | P33: 0.08 | Q33: 2365 | R33: =P33*Q33 -> 189.2 | S33: 0.82 | T33: =R33*S33 -> 155.144
E34: 120804 | F34: بنایی با بلوک‌های بتنی پیش‌ساخته از بتن سبک اتوکلاو شده (بتن گازی) با ملات مخصوص به ضخامت حدود 25 سانتی‌متر | G34: متر مربع | H34: 1644000 | O34: پلاستر گچ | P34: 0.01 | Q34: 1000 | R34: =P34*Q34 -> 10 | S34: 1.99 | T34: =R34*S34 -> 19.9 | U34: بدون عایق
E35: 120805 | F35: بنایی با بلوک‌های بتنی پیش‌ساخته از بتن سبک اتوکلاو شده (بتن گازی) با ملات مخصوص به ضخامت حدود 30 سانتی‌متر | G35: متر مربع | H35: 2048000 | O35: مجموع | T35: =SUM(T31:T34) -> 441.844 | U35: =SUM(T31:T34) -T32 -> 276.644
E36: 120806 | F36: بنایی با بلوک‌های بتنی پیش‌ساخته از بتن سبک اتوکلاو شده (بتن گازی) با ملات مخصوص به ضخامت تا 8 سانتی‌متر | G36: متر مربع | H36: 695500 | L36: 3.42 | M36: Aluminum-clad sandwich panel | N36: دیوار ساندویچ پانل آلومینیومی | O36: فوم عایق پلی‌یورتان | P36: 0.04 | Q36: 32 | R36: =P36*Q36 -> 1.28 | S36: 123 | T36: =R36*S36 -> 157.44 | U36: 743 | V36: بدون عایق
E37: 120807 | F37: بنایی با بلوک‌های بتنی پیش‌ساخته از بتن سبک اتوکلاو شده (بتن گازی) با ملات مخصوص به ضخامت حدود 12 سانتی‌متر | G37: متر مربع | H37: 940000 | O37: ورق خارجی آلومینیوم | P37: 0.002 | Q37: 2712 | R37: =P37*Q37 -> 5.424 | S37: 137 | T37: =R37*S37 -> 743.088 | U37: 10 cm
D38: اندود گچ و خاک | E38: 180201 | F38: شمشه‌گیری سطوح قائم و سقف‌ها، با ملات گچ و خاک یا گچ | G38: متر مربع | H38: 67200 | I38: 2 | O38: مجموع | T38: =SUM(T36:T37) -> 900.528
E39: 180202 | F39: اندود گچ و خاک به ضخامت تا 2.5 سانتی‌متر، روی سطوح قائم | G39: متر مربع | H39: 206000 | I39: 2 | L39: 3.43 | M39: Steel-clad sandwich panel | N39: دیوار ساندویچ پانل استیل | O39: فوم عایق پلی‌یورتان | P39: 0.04 | Q39: 32 | R39: =P39*Q39 -> 1.28 | S39: 123 | T39: =R39*S39 -> 157.44 | U39: 268 | V39: بدون عایق
D40: سفیدکاری | E40: 180215 | F40: سفیدکاری روی سطوح قائم و پرداخت آن با گچ کشته | G40: متر مربع | H40: 190500 | I40: 2 | O40: ورق خارجی فولادی | P40: 0.0018 | Q40: 7850 | R40: =P40*Q40 -> 14.13 | S40: 19.2 | T40: =R40*S40 -> 271.296 | U40: 10 cm
...

Sheet M04
A1: M04 | B1: دیوارهای داخلی Internal Walls | L1: M04 | M1: دیوارهای داخلی Internal Walls
A2: # | B2: Options | C2: گزینه | D2: WBS | E2: بند فهرست بها | F2: شرح بند | G2: واحد | H2: بهای واحد (ریال) | I2: مقدار | J2: بهای کل (ریال) | L2: # | M2: Options | N2: گزینه | O2: جزء تشکیل دهنده | P2: ضخامت(m) | Q2: چگالی(kg/m3) | R2: وزن(kg/m2) | S2: انرژی نهفته واحد وزن (MJ/kg) | T2: انرژی نهفته هر جزء(MJ/m2) | U2: انرژی نهفته کل(MJ/m2)
A3: 4.01 | B3: Common Brick Wall with internal & external plaster | C3: دیوار آجری معمولی با دو طرف گچ | D3: آجرچینی با آجر فشاری | E3: 110201 | F3: آجرکاری به ضخامت یک و نیم آجر و بیشتر با آجر فشاری و ملات ماسه سیمان 1:5 | G3: متر مکعب | H3: 5780000 | L3: 4.01 | M3: Common Brick Wall with internal & external plaster | N3: دیوار آجری معمولی با دو طرف گچ | O3: آجر فشاری | P3: 0.08 | Q3: 1800 | R3: =P3*Q3 -> 144 | S3: 4.95 | T3: =R3*S3 -> 712.8 | U3: 725
E4: 110205 | F4: دیوار یک آجره با آجر فشاری و ملات ماسه سیمان 1:5 | G4: متر مربع | H4: 1316000 | O4: اندود گچ و خاک | P4: 0.01 | Q4: 1600 | R4: =P4*Q4 -> 16 | S4: 1 | T4: =R4*S4 -> 16 | U4: 10 cm
E5: 110208 | F5: دیوار نیم آجره با آجر فشاری و ملات ماسه سیمان 1:5 | G5: متر مربع | H5: 731000 | I5: 1 | O5: پلاستر گچ | P5: 0.01 | Q5: 1000 | R5: =P5*Q5 -> 10 | S5: 1.99 | T5: =R5*S5 -> 19.9
D6: اندود گچ و خاک | E6: 180201 | F6: شمشه‌گیری سطوح قائم و سقف‌ها، با ملات گچ و خاک یا گچ | G6: متر مربع | H6: 67200 | I6: 2 | T6: =SUM(T3:T5) -> 748.7
E7: 180202 | F7: اندود گچ و خاک به ضخامت تا 2.5 سانتی‌متر، روی سطوح قائم | G7: متر مربع | H7: 206000 | I7: 2 | L7: 4.02 | M7: Cored (with holes) bricks with internal & external plaster | N7: دیوار آجری مجوف با دو طرف گچ | O7: آجر مجوف | P7: 0.08 | Q7: 1800 | R7: =P7*Q7*0.5 -> 72 | S7: 4.95 | T7: =R7*S7 -> 356.4 | U7: 379
D8: سفیدکاری | E8: 180215 | F8: سفیدکاری روی سطوح قائم و پرداخت آن با گچ کشته | G8: متر مربع | H8: 190500 | I8: 2 | O8: اندود گچ و خاک | P8: 0.01 | Q8: 1600 | R8: =P8*Q8 -> 16 | S8: 1 | T8: =R8*S8 -> 16 | U8: 10 cm
F9: مجموع | G9: متر مربع | H9: =SUMPRODUCT(H3:H8,I3:I8) -> 1658400 | O9: پلاستر گچ | P9: 0.01 | Q9: 1000 | R9: =P9*Q9 -> 10 | S9: 1.99 | T9: =R9*S9 -> 19.9
A10: 4.02 | B10: Cored (with holes) bricks with internal & external plaster | C10: دیوار آجری مجوف با دو طرف گچ | D10: آجرچینی با آجر ماشینی سوراخ‌‎دار | E10: 110501 | F10: آجرکاری به ضخامت یک و نیم آجر و بیشتر با آجر ماشینی سواخ‌دار به ابعاد آجر فشاری و ملات ماسه سیمان 1:5 | G10: متر مکعب | H10: 6943000 | T10: =SUM(T7:T9) -> 392.3
E11: 110502 | F11: دیوار یک آجره با آجر ماشینی سواخ‌دار به ابعاد آجر فشاری، با ملات ماسه سیمان 1:5 | G11: متر مربع | H11: 1607000 | L11: 4.03 | M11: Honeycomb Clay Blocks with internal & external plaster | N11: دیوار با بلوک سفالی با دو طرف گچ | O11: بلوک سفالی | P11: 0.08 | Q11: 815 | R11: =P11*Q11 -> 65.2 | S11: 2.02 | T11: =R11*S11 -> 131.704 | U11: 173
E12: 110503 | F12: دیوار نیم آجره با آجر ماشینی سواخ‌دار به ابعاد آجر فشاری، با ملات ماسه سیمان 1:5 | G12: متر مربع | H12: 866500 | I12: 1 | O12: اندود گچ و خاک | P12: 0.01 | Q12: 1600 | R12: =P12*Q12 -> 16 | S12: 1 | T12: =R12*S12 -> 16 | U12: 10 cm
D13: اندود گچ و خاک | E13: 180201 | F13: شمشه‌گیری سطوح قائم و سقف‌ها، با ملات گچ و خاک یا گچ | G13: متر مربع | H13: 67200 | I13: 2 | O13: پلاستر گچ | P13: 0.01 | Q13: 1000 | R13: =P13*Q13 -> 10 | S13: 1.99 | T13: =R13*S13 -> 19.9
E14: 180202 | F14: اندود گچ و خاک به ضخامت تا 2.5 سانتی‌متر، روی سطوح قائم | G14: متر مربع | H14: 206000 | I14: 2 | T14: =SUM(T11:T13) -> 167.604
D15: سفیدکاری | E15: 180215 | F15: سفیدکاری روی سطوح قائم و پرداخت آن با گچ کشته | G15: متر مربع | H15: 190500 | I15: 2 | L15: 4.04 | M15: Medium Weight Hollow Concrete Blocks | N15: دیوار با بلوک لیکا با دو طرف گچ | O15: بلوک لیکا | P15: 0.08 | Q15: 1606 | R15: =P15*Q15 -> 128.48 | S15: 0.66 | T15: =R15*S15 -> 84.7968 | U15: 128
F16: مجموع | G16: متر مربع | H16: =SUMPRODUCT(H10:H15,I10:I15) -> 1793900 | O16: اندود گچ و خاک | P16: 0.01 | Q16: 1600 | R16: =P16*Q16 -> 16 | S16: 1 | T16: =R16*S16 -> 16 | U16: 10 cm
A17: 4.03 | B17: Honeycomb Clay Blocks with internal & external plaster | C17: دیوار با بلوک سفالی با دو طرف گچ | D17: آجرچینی با بلوک سفالی | E17: 110401 | F17: دیوار به ضخامت 7 تا 11 سانتی‌متر با بلوک سفال و ملات ماسه سیمان 1:5 | G17: متر مکعب | H17: 5690000 | I17: 0.1 | O17: پلاستر گچ | P17: 0.01 | Q17: 1000 | R17: =P17*Q17 -> 10 | S17: 1.99 | T17: =R17*S17 -> 19.9
E18: 110402 | F18: دیوار به ضخامت بیش از 11 تا 22 سانتی‌متر با بلوک سفال و ملات ماسه سیمان 1:5 | G18: متر مکعب | H18: 5419000 | T18: =SUM(T15:T17) -> 120.6968
E19: 110403 | F19: آجرکاری به ضخامت بیش از 22 سانتی‌متر با بلوک سفال و ملات ماسه سیمان 1:5 | G19: متر مکعب | H19: 5329000 | L19: 4.06 | M19: Autoclaved Aerated Concrete Blocks | N19: دیوار با بلوک بتنی سبک AAC (هبلکس و ...) | O19: بلوک AAC | P19: 0.08 | Q19: 471 | R19: =P19*Q19 -> 37.68 | S19: 3.54 | T19: =R19*S19 -> 133.3872 | U19: 174
D20: اندود گچ و خاک | E20: 180201 | F20: شمشه‌گیری سطوح قائم و سقف‌ها، با ملات گچ و خاک یا گچ | G20: متر مربع | H20: 67200 | I20: 2 | O20: اندود گچ و خاک | P20: 0.01 | Q20: 1600 | R20: =P20*Q20 -> 16 | S20: 1 | T20: =R20*S20 -> 16 | U20: 10 cm
E21: 180202 | F21: اندود گچ و خاک به ضخامت تا 2.5 سانتی‌متر، روی سطوح قائم | G21: متر مربع | H21: 206000 | I21: 2 | O21: پلاستر گچ | P21: 0.01 | Q21: 1000 | R21: =P21*Q21 -> 10 | S21: 1.99 | T21: =R21*S21 -> 19.9
D22: سفیدکاری | E22: 180215 | F22: سفیدکاری روی سطوح قائم و پرداخت آن با گچ کشته | G22: متر مربع | H22: 190500 | I22: 2 | T22: =SUM(T19:T21) -> 169.2872
F23: مجموع | G23: متر مربع | H23: =SUMPRODUCT(H17:H22,I17:I22) -> 1496400 | L23: 4.11 | M23: Precast EPS-based Concrete Panels | N23: دیوار بتنی پیش‌ساخته (والکریت) | O23: بلوک پیش‌ساخته بتنی | P23: 0.1 | Q23: - | R23: - | S23: - | T23: 366 | U23: 366
A24: 4.04 | B24: Medium Weight Hollow Concrete Blocks | C24: دیوار با بلوک لیکا با دو طرف گچ | D24: بنایی با بلوک سیمانی لیکا | E24: 121001 | F24: بنایی با بلوک سیمانی سبک توخالی کف‌پر تهیه شده با دانه رس منبسط شده، به ضخامت تا 10 سانتی‌متر با ملات ماسه و سیمان 1:5 | G24: متر مربع | H24: 861500 | I24: 1 | O24: پلاستر گچ | P24: 0.01 | Q24: 1000 | R24: =P24*Q24 -> 10 | S24: 1.99 | T24: =R24*S24 -> 19.9 | U24: 10 cm
E25: 121002 | F25: بنایی با بلوک سیمانی سبک توخالی کف‌پر تهیه شده با دانه رس منبسط شده، به ضخامت 12 تا 15 سانتی‌متر با ملات ماسه و سیمان 1:5 | G25: متر مربع | H25: 1046000
E26: 121003 | F26: بنایی با بلوک سیمانی سبک توخالی کف‌پر تهیه شده با دانه رس منبسط شده، به ضخامت 17 تا 20 سانتی‌متر با ملات ماسه و سیمان 1:5 | G26: متر مربع | H26: 127000
D27: اندود گچ و خاک | E27: 180201 | F27: شمشه‌گیری سطوح قائم و سقف‌ها، با ملات گچ و خاک یا گچ | G27: متر مربع | H27: 67200 | I27: 2 | L27: 4.26 | M27: Plasterboards on metal studs with insulation | N27: دیوار پانل گچی با فریم فلزی با عایق | O27: پانل گچی | P27: 0.02 | Q27: 840 | R27: =P27*Q27 -> 16.8 | S27: 4.1 | T27: =R27*S27 -> 68.88 | U27: 353
E28: 180202 | F28: اندود گچ و خاک به ضخامت تا 2.5 سانتی‌متر، روی سطوح قائم | G28: متر مربع | H28: 206000 | I28: 2 | O28: زیرسازی فلزی | P28: - | Q28: - | R28: 6.4 | S28: 19.2 | T28: =R28*S28 -> 122.88 | U28: 10 cm
D29: سفیدکاری | E29: 180215 | F29: سفیدکاری روی سطوح قائم و پرداخت آن با گچ کشته | G29: متر مربع | H29: 190500 | I29: 2 | O29: عایق (پشم سنگ) | P29: 0.1 | Q29: 31 | R29: =P29*Q29 -> 3.1 | S29: 19.1 | T29: =R29*S29 -> 59.21
F30: مجموع | G30: متر مربع | H30: =SUMPRODUCT(H24:H29,I24:I29) -> 1788900 | T30: =SUM(T27:T29) -> 250.97
A31: 4.06 | B31: Autoclaved Aerated Concrete Blocks | C31: دیوار با بلوک بتنی سبک AAC (هبلکس و ...) | D31: بلوک از جنس بتن سبک | E31: 120801 | F31: بنایی با بلوک‌های بتنی پیش‌ساخته از بتن سبک اتوکلاو شده (بتن گازی) با ملات مخصوص به ضخامت حدود 10 سانتی‌متر | G31: متر مربع | H31: 829500 | I31: 1 | L31: 4.28 | M31: 3-D Wire panel with 'shot-crete' both sides -- with insulation | N31: 3D پانل با شاتکریت طرفین با عایق پلی‌استایرن | O31: سازه مشبک آرماتور | P31: - | Q31: - | R31: 8 | S31: 12.7 | T31: =R31*S31 -> 101.6 | U31: 387
E32: 120802 | F32: بنایی با بلوک‌های بتنی پیش‌ساخته از بتن سبک اتوکلاو شده (بتن گازی) با ملات مخصوص به ضخامت حدود 15 سانتی‌متر | G32: متر مربع | H32: 1094000 | O32: عایق (پلی‌استایرن) | P32: 0.05 | Q32: 20 | R32: =P32*Q32 -> 1 | S32: 82.6 | T32: =R32*S32 -> 82.6 | U32: 10 cm
E33: 120803 | F33: بنایی با بلوک‌های بتنی پیش‌ساخته از بتن سبک اتوکلاو شده (بتن گازی) با ملات مخصوص به ضخامت حدود 20 سانتی‌متر | G33: متر مربع | H33: 1419000 | O33: بتن شاتکریت | P33: 0.06 | Q33: 2365 | R33: =P33*Q33 -> 141.9 | S33: 0.82 | T33: =R33*S33 -> 116.358
E34: 120804 | F34: بنایی با بلوک‌های بتنی پیش‌ساخته از بتن سبک اتوکلاو شده (بتن گازی) با ملات مخصوص به ضخامت حدود 25 سانتی‌متر | G34: متر مربع | H34: 1644000 | O34: پلاستر گچ | P34: 0.01 | Q34: 1000 | R34: =P34*Q34 -> 10 | S34: 1.99 | T34: =R34*S34 -> 19.9
E35: 120805 | F35: بنایی با بلوک‌های بتنی پیش‌ساخته از بتن سبک اتوکلاو شده (بتن گازی) با ملات مخصوص به ضخامت حدود 30 سانتی‌متر | G35: متر مربع | H35: 2048000 | T35: =SUM(T31:T34) -> 320.458
E36: 120806 | F36: بنایی با بلوک‌های بتنی پیش‌ساخته از بتن سبک اتوکلاو شده (بتن گازی) با ملات مخصوص به ضخامت تا 8 سانتی‌متر | G36: متر مربع | H36: 695500
E37: 120807 | F37: بنایی با بلوک‌های بتنی پیش‌ساخته از بتن سبک اتوکلاو شده (بتن گازی) با ملات مخصوص به ضخامت حدود 12 سانتی‌متر | G37: متر مربع | H37: 940000
D38: اندود گچ و خاک | E38: 180201 | F38: شمشه‌گیری سطوح قائم و سقف‌ها، با ملات گچ و خاک یا گچ | G38: متر مربع | H38: 67200 | I38: 2
E39: 180202 | F39: اندود گچ و خاک به ضخامت تا 2.5 سانتی‌متر، روی سطوح قائم | G39: متر مربع | H39: 206000 | I39: 2
D40: سفیدکاری | E40: 180215 | F40: سفیدکاری روی سطوح قائم و پرداخت آن با گچ کشته | G40: متر مربع | H40: 190500 | I40: 2
...

Sheet M05
A1: M05 | B1: کفسازی نهایی Flooring | L1: M05 | M1: کفسازی نهایی Flooring
A2: # | B2: Options | C2: گزینه | D2: WBS | E2: بند فهرست بها | F2: شرح بند | G2: واحد | H2: بهای واحد (ریال) | I2: مقدار | J2: بهای کل (ریال) | L2: # | M2: Options | N2: گزینه | O2: جزء تشکیل دهنده | P2: ضخامت(m) | Q2: چگالی(kg/m3) | R2: وزن(kg/m2) | S2: انرژی نهفته واحد وزن (MJ/kg) | T2: انرژی نهفته هر جزء(MJ/m2) | U2: انرژی نهفته کل(MJ/m2)
A3: 5.01 | B3: Ceramic Tile | C3: کف سرامیک | D3: کاشی کاری با کاشی سرامیکی | E3: 200321 | F3: تهیه و نصب کاشی‌های سرامیکی لعاب‌‌دار یا بدون لعاب روی سطوح افقی با سطح تا 16 دسی‌متر مربع | G3: متر مربع | H3: 1215000 | L3: 5.01 | M3: Ceramic Tile | N3: کف سرامیک | O3: سرامیک | P3: 0.01 | Q3: 2000 | R3: =P3*Q3 -> 20 | S3: 7.96 | T3: =R3*S3 -> 159.2 | U3: 199
E4: 200322 | F4: تهیه و نصب کاشی‌های سرامیکی لعاب‌‌دار یا بدون لعاب روی سطوح افقی با سطح بیش از 16 تا 25 دسی‌متر مربع | G4: متر مربع | H4: 1313000 | I4: 1 | O4: ملات ماسه سیمان | P4: 0.01 | Q4: 1174 | R4: =P4*Q4 -> 11.74 | S4: 2.43 | T4: =R4*S4 -> 28.5282 | U4: 1 cm
E5: 200323 | F5: تهیه و نصب کاشی‌های سرامیکی لعاب‌‌دار یا بدون لعاب روی سطوح افقی با سطح بیش از 25 تا 36 دسی‌متر مربع | G5: متر مربع | H5: 1305000 | O5: ملات بندکشی | P5: 0.005 | Q5: 1590 | R5: =P5*Q5 -> 7.95 | S5: 1.26 | T5: =R5*S5 -> 10.017
E6: 200324 | F6: تهیه و نصب کاشی‌های سرامیکی لعاب‌‌دار یا بدون لعاب روی سطوح افقی با سطح بیش از 36 تا 49 دسی‌متر مربع | G6: متر مربع | H6: 1401000 | N6: مجموع | T6: =SUM(T3:T5) -> 197.7452
E7: 200325 | F7: تهیه و نصب کاشی‌های سرامیکی لعاب‌‌دار یا بدون لعاب روی سطوح افقی با سطح بیش از 49 تا 64 دسی‌متر مربع | G7: متر مربع | H7: 1693000 | L7: 5.02 | M7: Vinyl Flooring | N7: کفپوش وینیل (PVC) | O7: کفپوش PVC | P7: - | Q7: - | R7: 3.2 | S7: 51.8 | T7: =R7*S7 -> 165.76 | U7: 164
E8: 200326 | F8: تهیه و نصب کاشی‌های سرامیکی لعاب‌‌دار یا بدون لعاب روی سطوح افقی با سطح بیش از 64 تا 72 دسی‌متر مربع | G8: متر مربع | H8: 1795000 | O8: ملات بندکشی | U8: 0.2 cm
F9: مجموع | G9: متر مربع | H9: =SUMPRODUCT(H3:H8,I3:I8) -> 1313000 | O9: چسب
A10: 5.02 | B10: Vinyl Flooring | C10: کفپوش وینیل (PVC) | D10: تهیه و نصب کف‌پوش P.V.C | E10: 230110 | F10: تهیه و نصب کف‌پوش P.V.C، به صورت رول و با ضخامت 1.5 تا 2 میلیمتر | G10: متر مربع | H10: 953500
E11: 230111 | F11: اضافه بها به ردیف 230110 به ازای افزایش هر میلیمتر ضخامت کف‌پوش P.V.C مازاد بر 2 میلیمتر تا 6 میلیمتر (کسر میلیمتر به تناسب محاسبه می‌شود) | G11: متر مربع | H11: 472500 | L11: 5.03 | M11: Stone Tiles/Slabs | N11: کف کاشی سنگی | O11: سنگ پلاک | P11: 0.01 | Q11: 2600 | R11: =P11*Q11 -> 26 | S11: 8.6 | T11: =R11*S11 -> 223.6 | U11: 264
E12: 230112 | F12: تهیه و نصب کف‌پوش P.V.C، به صورت تایل به ابعاد مختلف و با ضخامت 1.5 تا 2 میلیمتر | G12: متر مربع | H12: 1559000 | O12: ملات ماسه سیمان | P12: 0.01 | Q12: 1174 | R12: =P12*Q12 -> 11.74 | S12: 2.43 | T12: =R12*S12 -> 28.5282 | U12: 2 cm
E13: 230113 | F13: اضافه بها به ردیف 230112 به ازای افزایش هر میلیمتر ضخامت کف‌پوش P.V.C مازاد بر 2 میلیمتر تا 6 میلیمتر (کسر میلیمتر به تناسب محاسبه می‌شود) | G13: متر مربع | H13: 179500 | O13: ملات بندکشی | P13: 0.005 | Q13: 1590 | R13: =P13*Q13 -> 7.95 | S13: 1.26 | T13: =R13*S13 -> 10.017
E14: 230114 | F14: تهیه و نصب کف‌پوش P.V.C ضد باکتری، به صورت رول و با ضخامت 1.5 تا 2 میلیمتر | G14: متر مربع | H14: 1653000 | I14: 1 | T14: =SUM(T11:T13) -> 262.1452
E15: 230115 | F15: اضافه بها به ردیف 230114 به ازای افزایش هر میلیمتر ضخامت کف‌پوش P.V.C ضد باکتری مازاد بر 2 میلیمتر تا 6 میلیمتر (کسر میلیمتر به تناسب محاسبه می‌شود) | G15: متر مربع | H15: 430000 | L15: 5.04 | M15: Finished Concrete Floor | N15: کف بتنی | O15: کفسازی بتنی | P15: 0.02 | Q15: 2365 | R15: =P15*Q15 -> 47.3 | S15: 1.45 | T15: =R15*S15 -> 68.585 | U15: 70
E16: 230116 | F16: تهیه و نصب کف‌پوش P.V.C ضد جریان الکتریسیته ساکن، به صورت رول و با ضخامت 1.5 تا 2 میلیمتر | G16: متر مربع | H16: 1844000 | U16: 3.5 cm
E17: 230117 | F17: تهیه و نصب کف‌پوش P.V.C ضد جریان الکتریسیته ساکن، به صورت تایل به ابعاد مختلف و با ضخامت 1.5 تا 2 میلیمتر | G17: متر مربع | H17: 2131000
F18: مجموع | G18: متر مربع | H18: =SUMPRODUCT(H10:H17,I10:I17) -> 1653000
A19: 5.03 | B19: Stone Tiles/Slabs | C19: کف کاشی سنگی | D19: تهیه و نصب سنگ پلاک | E19: 220110-220157 | F19: میانگین تهیه و نصب انواع سنگ پلاک تراورتن (فهرست بها) در سطوح افقی | G19: متر مربع | H19: 2753000 | L19: 5.06 | M19: Terrazzo Tiles | N19: کاشی موزاییک | O19: موزاییک پایه سیمانی | P19: 0.02 | Q19: 1580 | R19: =P19*Q19 -> 31.6 | S19: 1.88 | T19: =R19*S19 -> 59.408 | U19: 99
E20: 220205-220215 | F20: میانگین تهیه و نصب انواع سنگ پلاک سنگ آهک (فهرست بها) در سطوح افقی | G20: متر مربع | H20: 1970000 | O20: ملات ماسه سیمان | P20: 0.01 | Q20: 1174 | R20: =P20*Q20 -> 11.74 | S20: 2.43 | T20: =R20*S20 -> 28.5282 | U20: 2 cm
E21: 220320-220355 | F21: میانگین تهیه و نصب انواع سنگ پلاک مرمیت (فهرست بها) در سطوح افقی | G21: متر مربع | H21: 2252000 | O21: ملات بندکشی | P21: 0.005 | Q21: 1590 | R21: =P21*Q21 -> 7.95 | S21: 1.26 | T21: =R21*S21 -> 10.017
E22: 220410-220424 | F22: میانگین تهیه و نصب انواع سنگ پلاک چینی (فهرست بها) در سطوح افقی | G22: متر مربع | H22: 2894000 | T22: =SUM(T19:T21) -> 97.9532
E23: 220510-220546 | F23: میانگین تهیه و نصب انواع سنگ پلاک گرانیت (فهرست بها) در سطوح افقی | G23: متر مربع | H23: 2785000 | L23: 5.08 | M23: Laminated Wooden Flooring | N23: کفپوش لمینت | O23: کفپوش لمینت چوبی | P23: - | Q23: - | R23: 6.5 | S23: 36.4 | T23: =R23*S23 -> 236.6 | U23: 277
E24: 220110-220550 | F24: میانگین تهیه و نصب انواع سنگ پلاک (فهرست بها) تراورتن، سنگ آهک(لایم استون)، مرمریت، چینی، گرانیت | G24: متر مربع | H24: 2540000 | I24: 1 | O24: زیرسازی | P24: 0.04 | Q24: 1174 | R24: =P24*Q24 -> 46.96 | S24: 2.43 | U24: 1 cm
F25: مجموع | G25: متر مربع | H25: =SUMPRODUCT(H19:H24,I19:I24) -> 2540000 | O25: ملات بندکشی | P25: 0.005 | Q25: 1590 | R25: =P25*Q25 -> 7.95 | S25: 1.26
A26: 5.04 | B26: Finished Concrete Floor - Screed | C26: کف اپوکسی | D26: تهیه و اجرای کف‌پوش اپوکسی | E26: 230350 | F26: تهیه مصالح و اجرای کف‌پوش اپوکسی با بنیان رزین اپوکسی و سخت‌کننده مربوط شامل قشر آستر، لایه میانی و لایه رویه به ضخامت تا 2 میلیمتر | G26: متر مربع | H26: 2403000 | I26: 1
E27: 230351 | F27: اضافه‌بها به ردیف 230350 به ازای هر میلیمتر افزایش ضخامت مازاد بر ۲ میلیمتر تا 5 میلیمتر | G27: متر مربع | H27: 1088000
E28: 230352 | F28: اضافه‌بها به ردیف 230350 در صورتی که کف‌پوش از نوع آنتی‌باکتریال باشد | G28: متر مربع | H28: 895000 | I28: 1
F29: مجموع | G29: متر مربع | H29: =SUMPRODUCT(H26:H28,I26:I28) -> 3298000
A30: 5.06 | B30: Terrazzo Tiles | C30: کف‌سازی موزاییک | D30: فرش کف با موزاییک | E30: 210403 | F30: فرش کف با موزاییک پرسی یا ویبره‌ای با سطح صاف | G30: متر مربع | H30: 656500
E31: 210511 | F31: فرش کف با موزاییک ماشینی پرسی دو لایه با سطح صاف با ملات ماسه سیمان 1:5 | G31: متر مربع | H31: 772000 | I31: 1
E32: 210513 | F32: فرش کف با موزاییک ماشینی پرسی تک لایه با سطح صاف با ملات ماسه سیمان 1:5 | G32: متر مربع | H32: 945000
F33: مجموع | G33: متر مربع | H33: =SUMPRODUCT(H30:H32,I30:I32) -> 772000
A34: 5.08 | B34: Laminated Wooden Flooring | C34: کفپوش لمینت چوبی | D34: تهیه و نصب کفپوش لمینت | E34: 191502 | F34: تهیه و نصب کف‌پوش لمینت به ضخامت حدود 8 میلیمتر | G34: متر مربع | H34: 1890000 | I34: 1
E35: 191505 | F35: اضافه‌بها به ردیف 191502، در صورتی که درجه مقاومت به سایش کف‌پوش لمینت، AC4 یا AC5 باشد | G35: متر مربع | H35: 157500
F36: مجموع | G36: متر مربع | H36: =SUMPRODUCT(H34:H35,I34:I35) -> 1890000

Sheet M06
A1: M06 | B1: فریم (قاب) پنجره ها Window Frames | L1: M06 | M1: فریم (قاب) پنجره ها Window Frames
A2: # | B2: Options | C2: گزینه | D2: WBS | E2: بند فهرست بها | F2: شرح بند | G2: واحد | H2: بهای واحد (ریال) | I2: مقدار | J2: بهای کل (ریال) | L2: # | M2: Options | N2: گزینه | O2: جزء تشکیل دهنده | P2: ضخامت(m) | Q2: چگالی(kg/m3) | R2: وزن(kg) | S2: انرژی نهفته واحد وزن (MJ/kg) | T2: انرژی نهفته هر جزء(MJ/m2) | U2: انرژی نهفته کل(MJ/m2)
A3: 6.01 | B3: Aluminium | C3: فریم پنجره آلومینیوم | L3: 6.01 | M3: Aluminium | N3: فریم پنجره آلومینیوم
A4: 6.02 | B4: Steel | C4: فریم پنجره استیل | L4: 6.02 | M4: Steel | N4: فریم پنجره استیل
A5: 6.03 | B5: Timber | C5: فریم پنجره چوبی | L5: 6.03 | M5: Timber | N5: فریم پنجره چوبی
A6: 6.04 | B6: UPVC | C6: فریم پنجره UPVC | L6: 6.04 | M6: UPVC | N6: فریم پنجره UPVC
A7: 6.05 | B7: Aluminium clad timber | C7: فریم پنجره چوب و آلومینیوم | L7: 6.05 | M7: Aluminium clad timber | N7: فریم پنجره چوب و آلومینیوم

Sheet M07&M08
A1: M07 & M08 | B1: عایق Insulation | L1: M07 & M08 | M1: عایق Insulation | U1: EDGE
A2: # | B2: Options | C2: گزینه | D2: WBS | E2: بند فهرست بها | F2: شرح بند | G2: واحد | H2: بهای واحد (ریال) | I2: مقدار | J2: بهای کل (ریال) | L2: # | M2: Options | N2: گزینه | O2: جزء تشکیل دهنده | P2: ضخامت(m) | Q2: چگالی(kg/m3) | R2: وزن(kg) | S2: انرژی نهفته واحد وزن (MJ/kg) | T2: انرژی نهفته هر جزء(MJ/m2) | U2: انرژی نهفته کل(MJ/m2)
A3: 7.01 | B3: Polystyrene | C3: پلی استایرن - یونولیت | D3: عایق‌کاری با پلی استایرن | E3: 140213 | F3: عایق‌کاری با پلی‌استایرن منبسط شده به ضخامت 15 میلی‌متر و وزن مخصوص 15 کیلوگرم بر مترمکعب | G3: متر مربع | H3: 202000 | L3: 7.01 | M3: Polystyrene | N3: پلی استایرن - یونولیت | P3: 0.05 | Q3: 20 | R3: =P3*Q3 -> 1 | S3: 82.6 | T3: =R3*S3 -> 82.6 | U3: 83
E4: 140214 | F4: اضافه‌بها به ردیف 140213، به ازای افزایش هر کیلوگرم مقدار عایق مصرفی در هر مترمکعب ناشی از افزایش ضخامت یا وزن مخصوص آن (کسر کیلوگرم به تناسب محاسبه می‌شود) | G4: کیلوگرم | H4: 616000 | L4: 7.02 | M4: Mineral Wool | N4: پشم سنگ | P4: 0.05 | Q4: 31 | R4: =P4*Q4 -> 1.55 | S4: 19.1 | T4: =R4*S4 -> 29.605 | U4: 30
A5: 7.02 | B5: Mineral Wool | C5: پشم سنگ | D5: عایق‌کاری با پشم سنگ | E5: 140119 | F5: عایق‌کاری حرارتی با عایق پشم سنگ به صورت پانل و بدون روکش، به ضخامت 30 میلی‌متر و به وزن مخصوص 50 کیلوگرم بر مترمکعب | G5: متر مربع | H5: 372000 | L5: 7.03 | M5: Glass Wool | N5: پشم شیشه | P5: 0.05 | Q5: 15 | R5: =P5*Q5 -> 0.75 | T5: =R5*S5 -> 0 | U5: 30
E6: 140120 | F6: اضافه‌بها به ردیف 140119، به ازای افزایش هر کیلوگرم مقدار عایق مصرفی در هر مترمکعب ناشی از افزایش ضخامت یا وزن مخصوص آن (کسر کیلوگرم به تناسب محاسبه می‌شود) | G6: کیلوگرم | H6: 185000 | L6: 7.04 | M6: Polyurethane | N6: پلی اورتان | P6: 0.05 | Q6: 32 | R6: =P6*Q6 -> 1.6 | S6: 123 | T6: =R6*S6 -> 196.8 | U6: 197
A7: 7.03 | B7: Glass Wool | C7: پشم شیشه | D7: عایق‌کاری با پشم شیشه | E7: 140113 | F7: عایق‌کاری حرارتی با عایق پشم شیشه به صورت پانل و بدون روکش، به ضخامت 25 میلی‌متر و به وزن مخصوص 26 کیلوگرم بر مترمکعب | G7: متر مربع | H7: 294500 | L7: - | M7: Mineral Wool | N7: 29% Glass Wool at 15 kg/m3 | Q7: 15
E8: 140114 | F8: اضافه‌بها به ردیف 140113، به ازای افزایش هر کیلوگرم مقدار عایق مصرفی در هر مترمکعب ناشی از افزایش ضخامت یا وزن مخصوص آن (کسر کیلوگرم به تناسب محاسبه می‌شود) | G8: کیلوگرم | H8: 213500 | N8: 71% stone wool at 37 kg/m3 | Q8: 37
A9: 7.04 | B9: Polyurethane | C9: پلی‌یورتان | D9: عایق‌کاری با پلی‌یورتان | E9: 140211 | F9: عایق‌کاری حرارتی با عایق پلی‌یورتان به ضخامت 15 میلی‌متر و وزن مخصوص 30 کیلوگرم بر مترمکعب | G9: متر مربع | H9: 615000
E10: 140212 | F10: اضافه‌بها به ردیف 140211، به ازای افزایش هر کیلوگرم مقدار عایق مصرفی در هر مترمکعب ناشی از افزایش ضخامت یا وزن مخصوص آن (کسر کیلوگرم به تناسب محاسبه می‌شود) | G10: کیلوگرم | H10: 1227000

Sheet Social
A1: 1 | B1: in-situ conc | C1: 3.2307692
A2: 2 | B2: in-situ conc | C2: 3.2307692
A3: 3 | B3: in-situ conc | C3: 3.2307692
A4: 4 | B4: waffle slab | C4: 4.437247
A5: 5 | B5: polystyrene filler slab | C5: 3.7246964
A6: 6 | B6: conc filler slab | C6: 2.9595142
A7: 7 | B7: composite | C7: 3.659919
A8: 8 | B8: epoxy | C8: 3.2550607
A9: 9 | B9: ceramic floor | C9: 3.4291498
A10: 10 | B10: stone | C10: 3.9919028
A11: 11 | B11: terazzo | C11: 2.0040486
A12: 12 | B12: laminated | C12: 4.1093117
... A31: 31 | B31: plasterboard | C31: 4.1700405
